Workbook

Sheet Risk Table
A12: Family Category | B12: Risk ID | C12: Risk Name | D12: Risk Description | E12: Consequence | F12: Risk Owner | G12: Probability | H12: Impact | I12: Pre-Mitigation Risk Level | J12: Pre-Mitigation Score | K12: Average Risk Score (per Family) | L12: Risk Level (per Family) | M12: Family Weight | N12: Weighted Score | O12: Total Weighted Score | P12: Mitigation Plan | Q12: Objective | R12: Post-Mitigation Probability | S12: Post-Mitigation Impact | T12: Post-Mitigation Risk Level | U12: Post-Mitigation Score | V12: Average Risk Score (per Family) | W12: Risk Level (per Family) | X12: Family Weight | Y12: Weighted Score | Z12: Risk Improvement Margin | AA12: Mitigation Effect | AB12: Average margin (per Family) | AC12: Mitigation Effect (per Family) | AD12: Total Weighted Score
A13: Operational Risks | B13: OP1 | C13: Product Supply Shortages | D13: Frequent shortages of cleaning materials, uniforms, or basic supplies due to poor stock tracking | E13: Service disruption and declining client satisfaction due to incomplete equipment availability; staff forced to improvise or delay tasks until materials arrive. | F13: Operations Manager | G13: High | H13: High | I13: =INDEX($H$52:$L$56,MATCH(G13,$G$52:$G$56,0),MATCH(H13,$H$51:$L$51,0)) -> Critical | J13: =VLOOKUP(I13, $H$61:$J$64, 3, FALSE) -> 7 | K13: =AVERAGE(J13:J16) -> 6.5 | L13: {=_xlfn.XLOOKUP(1, (K13>=$G$77:$G$80)*(K13<=$H$77:$H$80), $I$77:$I$80)} -> Critical | M13: =VLOOKUP($A13, $H$68:$J$72, 3, FALSE) -> 0.35 | N13: =IF(J13<>"",J13*$M$13,"") -> 2.45 | O13: =AVERAGE(N13:N16) -> 2.275 | P13: Implement a monthly inventory monitoring system, assign a responsible person to manage supply levels, and establish agreements with alternative local suppliers for urgent needs. | Q13: To maintain consistent material availability, minimize service interruptions, and ensure rapid response to supplier delays through proactive stock control. | R13: Very Low | S13: Low | T13: =INDEX($H$52:$L$56,MATCH(R13,$G$52:$G$56,0),MATCH(S13,$H$51:$L$51,0)) -> Sustainable | U13: =VLOOKUP(T13, $H$61:$J$64, 3, FALSE) -> 0 | V13: =AVERAGE(U13:U16) -> 1.75 | W13: {=_xlfn.XLOOKUP(1, (V13>=$G$77:$G$80)*(V13<=$H$77:$H$80), $I$77:$I$80)} -> Sustainable | X13: =VLOOKUP($A13, $H$68:$J$72, 3, FALSE) -> 0.35 | Y13: =IF(U13<>"",U13*$X$13,"") -> 0 | Z13: =Y13-N13 -> -2.45 | AA13: {=INDEX($I$84:$I$88,MATCH(1,($Z13>=$G$84:$G$88)*($Z13<=$H$84:$H$88),0))} -> Strong Improvement | AB13: =AVERAGE(Z13:Z16) -> -1.6625 | AC13: {=INDEX($I$84:$I$88,MATCH(1,($AB13>=$G$84:$G$88)*($AB13<=$H$84:$H$88),0))} -> Strong Improvement | AD13: =AVERAGE(Y13:Y16) -> 0.6125
B14: OP2 | C14: Equipment Deterioration | D14: Aging and poorly maintained equipment, tools, and safety gear due to irregular servicing or delayed replacement decisions. | E14: Decline in operational efficiency, increased maintenance costs, and higher risk of service interruption or safety incidents when tools fail during work. | F14: Operations Manager | G14: High | H14: High | I14: =INDEX($H$52:$L$56,MATCH(G14,$G$52:$G$56,0),MATCH(H14,$H$51:$L$51,0)) -> Critical | J14: =VLOOKUP(I14, $H$61:$J$64, 3, FALSE) -> 7 | N14: =IF(J14<>"",J14*$M$13,"") -> 2.45 | P14: Develop and implement a structured annual maintenance plan; allocate a small annual budget for preventive replacement of critical tools and safety gear. | Q14: To minimize unplanned breakdowns, reduce maintenance expenses, and maintain consistent performance through proactive maintenance and replacement planning. | R14: Low | S14: Medium | T14: =INDEX($H$52:$L$56,MATCH(R14,$G$52:$G$56,0),MATCH(S14,$H$51:$L$51,0)) -> Moderate | U14: =VLOOKUP(T14, $H$61:$J$64, 3, FALSE) -> 2 | Y14: =IF(U14<>"",U14*$X$13,"") -> 0.7 | Z14: =Y14-N14 -> -1.75 | AA14: {=INDEX($I$84:$I$88,MATCH(1,($Z14>=$G$84:$G$88)*($Z14<=$H$84:$H$88),0))} -> Strong Improvement
B15: OP3 | C15: Poor Service Quality & Delays | D15: Inconsistent service quality and frequent delivery delays caused by insufficient supervision, unmonitored staff behavior, and lack of real-time feedback mechanisms. | E15: Reduced client trust and satisfaction; repeated complaints related to staff absenteeism, poor discipline, and inconsistent task completion. This can jeopardize contract renewals with key clients. | F15: Operations Supervisor | G15: Medium | H15: Very High | I15: =INDEX($H$52:$L$56,MATCH(G15,$G$52:$G$56,0),MATCH(H15,$H$51:$L$51,0)) -> Critical | J15: =VLOOKUP(I15, $H$61:$J$64, 3, FALSE) -> 7 | N15: =IF(J15<>"",J15*$M$13,"") -> 2.45 | P15: Implement a weekly supervision checklist, conduct monthly client satisfaction surveys. | Q15: To ensure consistent service quality, improve employee accountability, and strengthen client relationships through continuous supervision. | R15: Low | S15: High | T15: =INDEX($H$52:$L$56,MATCH(R15,$G$52:$G$56,0),MATCH(S15,$H$51:$L$51,0)) -> Severe | U15: =VLOOKUP(T15, $H$61:$J$64, 3, FALSE) -> 5 | Y15: =IF(U15<>"",U15*$X$13,"") -> 1.75 | Z15: =Y15-N15 -> -0.7 | AA15: {=INDEX($I$84:$I$88,MATCH(1,($Z15>=$G$84:$G$88)*($Z15<=$H$84:$H$88),0))} -> Strong Improvement
B16: OP4 | C16: Inefficient Delivery Process | D16: Inefficient delivery planning and poor route optimization for supply transport, leading to unnecessary trips, higher fuel consumption, and scheduling conflicts between branches. | E16: Frequent delays in material delivery, higher operating and fuel costs, and reduced productivity at work sites waiting for supplies. | F16: Logistics Manager | G16: Very High | H16: Medium | I16: =INDEX($H$52:$L$56,MATCH(G16,$G$52:$G$56,0),MATCH(H16,$H$51:$L$51,0)) -> Severe | J16: =VLOOKUP(I16, $H$61:$J$64, 3, FALSE) -> 5 | N16: =IF(J16<>"",J16*$M$13,"") -> 1.75 | P16: Consolidate supply requests and organize deliveries on a quarterly schedule for distant branches; optimize delivery routes and group orders to reduce transport frequency. | Q16: To improve delivery efficiency, lower fuel and transport expenses, and ensure materials reach each branch on time through better planning and route coordination. | R16: Medium | S16: Very Low | T16: =INDEX($H$52:$L$56,MATCH(R16,$G$52:$G$56,0),MATCH(S16,$H$51:$L$51,0)) -> Sustainable | U16: =VLOOKUP(T16, $H$61:$J$64, 3, FALSE) -> 0 | Y16: =IF(U16<>"",U16*$X$13,"") -> 0 | Z16: =Y16-N16 -> -1.75 | AA16: {=INDEX($I$84:$I$88,MATCH(1,($Z16>=$G$84:$G$88)*($Z16<=$H$84:$H$88),0))} -> Strong Improvement
A17: Marketing Risks | B17: M1 | C17: decreace Negative Client Feedback handling cause of retierement Client Relations Officer | D17: Repeated negative feedback or complaints from clients due to service inconsistencies or communication gaps. Most issues are currently managed directly by the Client Relations Officer, who resolves problems quickly through phone communication thanks to his long experience and professional network. However, he is nearing retirement, creating a potential gap in client management continuity. | E17: Short-term reputational impact and reduced client satisfaction if unresolved. In the future, loss of the current officer’s experience and personal client relationships could increase response time and reduce trust with long-term clients. | F17: HR Manager | G17: Very High | H17: High | I17: =INDEX($H$52:$L$56,MATCH(G17,$G$52:$G$56,0),MATCH(H17,$H$51:$L$51,0)) -> Critical | J17: =VLOOKUP(I17, $H$61:$J$64, 3, FALSE) -> 7 | K17: =AVERAGE(J17:J20) -> 5.25 | L17: {=_xlfn.XLOOKUP(1, (K17>=$G$77:$G$80)*(K17<=$H$77:$H$80), $I$77:$I$80)} -> Severe | M17: =VLOOKUP($A17, $H$68:$J$72, 3, FALSE) -> 0.05 | N17: =IF(J17<>"",J17*$M$17,"") -> 0.35 | O17: =AVERAGE(N17:N20) -> 0.2625 | P17: Assign one team member to work closely with the Client Relations Officer to learn his methods, maintain his client relationships, and document all contact information. The current officer should introduce this successor to key client contacts before retirement. Additionally, record all client complaints and feedback in a simple tracking sheet, reviewed monthly. | Q17: To ensure continuity in client relationship management, preserve institutional knowledge, and maintain the same quick and personal service level after the current officer’s retirement. Establishing a feedback record will also improve transparency and long-term service quality. | R17: Very High | S17: Low | T17: =INDEX($H$52:$L$56,MATCH(R17,$G$52:$G$56,0),MATCH(S17,$H$51:$L$51,0)) -> Moderate | U17: =VLOOKUP(T17, $H$61:$J$64, 3, FALSE) -> 2 | V17: =AVERAGE(U17:U20) -> 2.25 | W17: {=_xlfn.XLOOKUP(1, (V17>=$G$77:$G$80)*(V17<=$H$77:$H$80), $I$77:$I$80)} -> Moderate | X17: =VLOOKUP($A17, $H$68:$J$72, 3, FALSE) -> 0.05 | Y17: =IF(U17<>"",U17*$X$17,"") -> 0.1 | Z17: =Y17-N17 -> -0.25 | AA17: {=INDEX($I$84:$I$88,MATCH(1,($Z17>=$G$84:$G$88)*($Z17<=$H$84:$H$88),0))} -> Moderate Improvement | AB17: =AVERAGE(Z17:Z20) -> -0.15 | AC17: {=INDEX($I$84:$I$88,MATCH(1,($AB17>=$G$84:$G$88)*($AB17<=$H$84:$H$88),0))} -> Slight Improvement | AD17: =AVERAGE(Y17:Y20) -> 0.1125
B18: M2 | C18: Low Market Visibility | D18: Limited marketing presence and visibility in the private sector due to the absence of dedicated business development efforts or digital promotion. SBS primarily relies on long-term public contracts and personal connections, which limits opportunities to attract private-sector clients such as hotels, offices, and industrial companies. | E18: Missed growth opportunities and overreliance on public contracts. The company’s financial stability and client portfolio diversification are at risk if public tenders decrease or payment delays increase. | F18: General Manager | G18: High | H18: High | I18: =INDEX($H$52:$L$56,MATCH(G18,$G$52:$G$56,0),MATCH(H18,$H$51:$L$51,0)) -> Critical | J18: =VLOOKUP(I18, $H$61:$J$64, 3, FALSE) -> 7 | N18: =IF(J18<>"",J18*$M$17,"") -> 0.35 | P18: Recruit or assign a Commercial Agent responsible for approaching private-sector clients (e.g., hotels, offices, factories). The agent will prepare simple marketing materials (brochure or profile) and establish partnerships through business networks. | Q18: To expand SBS’s market presence by attracting private clients, reducing dependency on public-sector contracts, and ensuring long-term financial stability through diversified revenue streams. | R18: Medium | S18: Medium | T18: =INDEX($H$52:$L$56,MATCH(R18,$G$52:$G$56,0),MATCH(S18,$H$51:$L$51,0)) -> Moderate | U18: =VLOOKUP(T18, $H$61:$J$64, 3, FALSE) -> 2 | Y18: =IF(U18<>"",U18*$X$17,"") -> 0.1 | Z18: =Y18-N18 -> -0.25 | AA18: {=INDEX($I$84:$I$88,MATCH(1,($Z18>=$G$84:$G$88)*($Z18<=$H$84:$H$88),0))} -> Moderate Improvement
B19: M3 | C19: No Ambition for International Expansion | D19: Lack of strategic ambition or initiative to explore opportunities for providing services abroad. SBS has never discussed expanding operations internationally or networking with foreign partners, limiting its exposure to new markets. | E19: The company remains fully dependent on the domestic market and vulnerable to local economic instability. By not engaging internationally, SBS misses potential collaborations, growth opportunities, and visibility among regional or global security and facility service providers. | F19: General Manager | G19: Very High | H19: Medium | I19: =INDEX($H$52:$L$56,MATCH(G19,$G$52:$G$56,0),MATCH(H19,$H$51:$L$51,0)) -> Severe | J19: =VLOOKUP(I19, $H$61:$J$64, 3, FALSE) -> 5 | N19: =IF(J19<>"",J19*$M$17,"") -> 0.25 | P19: Participate in international fairs and exhibitions dedicated to security and cleaning service providers. Use these events to network with potential partners, learn about global market trends, and identify opportunities for regional or cross-border operations. | Q19: To encourage strategic openness and long-term growth by exposing management to international practices, building partnerships, and exploring new market opportunities through active participation in professional fairs. | R19: Medium | S19: High | T19: =INDEX($H$52:$L$56,MATCH(R19,$G$52:$G$56,0),MATCH(S19,$H$51:$L$51,0)) -> Severe | U19: =VLOOKUP(T19, $H$61:$J$64, 3, FALSE) -> 5 | Y19: =IF(U19<>"",U19*$X$17,"") -> 0.25 | Z19: =Y19-N19 -> 0 | AA19: {=INDEX($I$84:$I$88,MATCH(1,($Z19>=$G$84:$G$88)*($Z19<=$H$84:$H$88),0))} -> No Change
B20: M4 | C20: Low Innovation & Lack of New Services | D20: Limited investment in innovation and new service development. SBS continues to offer the same traditional cleaning and guarding services without adopting modern techniques, eco-friendly solutions. | E20: Gradual loss of competitiveness and market attractiveness, especially among private or international clients who increasingly value modern, sustainable, and efficient service solutions. | F20: General Manager | G20: Very High | H20: Low | I20: =INDEX($H$52:$L$56,MATCH(G20,$G$52:$G$56,0),MATCH(H20,$H$51:$L$51,0)) -> Moderate | J20: =VLOOKUP(I20, $H$61:$J$64, 3, FALSE) -> 2 | N20: =IF(J20<>"",J20*$M$17,"") -> 0.1 | P20: Launch a pilot eco-cleaning or smart service program in one branch. Test new environmentally friendly products and modern cleaning or security technologies. Evaluate client feedback and operational benefits before wider implementation. | Q20: To stimulate innovation within the company, improve service quality, and enhance SBS’s brand image by integrating sustainable and modern practices that align with global trends. | R20: Low | S20: Low | T20: =INDEX($H$52:$L$56,MATCH(R20,$G$52:$G$56,0),MATCH(S20,$H$51:$L$51,0)) -> Sustainable | U20: =VLOOKUP(T20, $H$61:$J$64, 3, FALSE) -> 0 | Y20: =IF(U20<>"",U20*$X$17,"") -> 0 | Z20: =Y20-N20 -> -0.1 | AA20: {=INDEX($I$84:$I$88,MATCH(1,($Z20>=$G$84:$G$88)*($Z20<=$H$84:$H$88),0))} -> Slight Improvement
A21: Financial Risks | B21: F1 | C21: Client Late Payments | D21: Recurring late payments from major public clients such as STEG, CNAM, and CNRPS, often exceeding agreed payment terms. These delays are common in public-sector contracts due to long administrative procedures and complex validation cycles. | E21: Cash-flow pressure that can delay salary payments and supplier settlements. Prolonged delays may affect daily operations, reduce liquidity, and limit the company’s ability to invest or respond to emergencies. | F21: Finance Manager | G21: Very High | H21: Very High | I21: =INDEX($H$52:$L$56,MATCH(G21,$G$52:$G$56,0),MATCH(H21,$H$51:$L$51,0)) -> Critical | J21: =VLOOKUP(I21, $H$61:$J$64, 3, FALSE) -> 7 | K21: =AVERAGE(J21:J24) -> 5.75 | L21: {=_xlfn.XLOOKUP(1, (K21>=$G$77:$G$80)*(K21<=$H$77:$H$80), $I$77:$I$80)} -> Severe | M21: =VLOOKUP($A21, $H$68:$J$72, 3, FALSE) -> 0.2 | N21: =IF(J21<>"",J21*$M$21,"") -> 1.4 | O21: =AVERAGE(N21:N24) -> 1.15 | P21: Negotiate partial advance payments in all new contracts, prioritize collaborations with faster-paying clients, and maintain a monthly monitoring table to track outstanding invoices and payment status. | Q21: To improve cash-flow stability and reduce financial stress by ensuring predictable revenue streams and faster recovery of client payments through proactive negotiation and tracking. | R21: Very High | S21: Medium | T21: =INDEX($H$52:$L$56,MATCH(R21,$G$52:$G$56,0),MATCH(S21,$H$51:$L$51,0)) -> Severe | U21: =VLOOKUP(T21, $H$61:$J$64, 3, FALSE) -> 5 | V21: =AVERAGE(U21:U24) -> 4.25 | W21: {=_xlfn.XLOOKUP(1, (V21>=$G$77:$G$80)*(V21<=$H$77:$H$80), $I$77:$I$80)} -> Moderate | X21: =VLOOKUP($A21, $H$68:$J$72, 3, FALSE) -> 0.2 | Y21: =IF(U21<>"",U21*$X$21,"") -> 1 | Z21: =Y21-N21 -> -0.4 | AA21: {=INDEX($I$84:$I$88,MATCH(1,($Z21>=$G$84:$G$88)*($Z21<=$H$84:$H$88),0))} -> Moderate Improvement | AB21: =AVERAGE(Z21:Z24) -> -0.3 | AC21: {=INDEX($I$84:$I$88,MATCH(1,($AB21>=$G$84:$G$88)*($AB21<=$H$84:$H$88),0))} -> Moderate Improvement | AD21: =AVERAGE(Y21:Y24) -> 0.85
B22: F2 | C22: Rising Operating Costs (Inflation) | D22: Continuous increase in operating costs caused by inflation, higher wages, and rising prices of cleaning materials, fuel, and equipment. Since most SBS contracts are fixed-price agreements, the company cannot adjust billing rates to match cost increases. | E22: Declining profit margins and reduced financial flexibility. Persistent inflation erodes profitability and limits the company’s ability to reinvest in equipment, staff training, or maintenance. | F22: Finance Manager | G22: Medium | H22: Medium | I22: =INDEX($H$52:$L$56,MATCH(G22,$G$52:$G$56,0),MATCH(H22,$H$51:$L$51,0)) -> Moderate | J22: =VLOOKUP(I22, $H$61:$J$64, 3, FALSE) -> 2 | N22: =IF(J22<>"",J22*$M$21,"") -> 0.4 | P22: Negotiate annual price adjustment clauses with major clients to partially reflect inflation. Purchase frequently used materials in bulk to secure better pricing and anticipate cost fluctuations. | Q22: To protect profit margins and ensure financial sustainability by securing more flexible contract terms and optimizing purchasing strategies against market price volatility. | R22: Medium | S22: Low | T22: =INDEX($H$52:$L$56,MATCH(R22,$G$52:$G$56,0),MATCH(S22,$H$51:$L$51,0)) -> Moderate | U22: =VLOOKUP(T22, $H$61:$J$64, 3, FALSE) -> 2 | Y22: =IF(U22<>"",U22*$X$21,"") -> 0.4 | Z22: =Y22-N22 -> 0 | AA22: {=INDEX($I$84:$I$88,MATCH(1,($Z22>=$G$84:$G$88)*($Z22<=$H$84:$H$88),0))} -> No Change
B23: F3 | C23: Dependence on Few Major Clients | D23: Strong dependence on a small number of large public clients such as STEG, CNAM, and CNRPS. More than half of SBS’s revenue relies on these contracts, which makes the company highly exposed to financial instability if one of them is lost or delayed. | E23: Losing a single major contract would significantly reduce monthly revenue, create cash-flow gaps, and potentially lead to workforce downsizing. Dependence on public clients also increases exposure to payment delays and administrative renewal risks. | F23: Business Development Manager | G23: High | H23: Very High | I23: =INDEX($H$52:$L$56,MATCH(G23,$G$52:$G$56,0),MATCH(H23,$H$51:$L$51,0)) -> Critical | J23: =VLOOKUP(I23, $H$61:$J$64, 3, FALSE) -> 7 | N23: =IF(J23<>"",J23*$M$21,"") -> 1.4 | P23: Recruit a Commercial Agent dedicated to prospecting and negotiating with private-sector clients (e.g., hotels, offices, factories). Develop simple company presentations and service offers to attract new clients and diversify the client base. | Q23: To reduce financial vulnerability by diversifying the company’s client portfolio, balancing public and private contracts, and ensuring long-term revenue stability. | R23: Medium | S23: High | T23: =INDEX($H$52:$L$56,MATCH(R23,$G$52:$G$56,0),MATCH(S23,$H$51:$L$51,0)) -> Severe | U23: =VLOOKUP(T23, $H$61:$J$64, 3, FALSE) -> 5 | Y23: =IF(U23<>"",U23*$X$21,"") -> 1 | Z23: =Y23-N23 -> -0.4 | AA23: {=INDEX($I$84:$I$88,MATCH(1,($Z23>=$G$84:$G$88)*($Z23<=$H$84:$H$88),0))} -> Moderate Improvement
B24: F4 | C24: Contract Loss from new uninformed Competition | D24: Increasing competition from informal or newly established companies that use aggressive price-cutting (penetration strategy) to win contracts. These competitors often lack professional standards or long-term stability but create pressure on SBS to lower prices. | E24: Risk of losing contracts to cheaper but less qualified competitors, resulting in sudden revenue loss and planning instability. Lower pricing in the market can also reduce profit margins and affect SBS’s ability to retain skilled staff. | F24: General Manager | G24: Low | H24: Very High | I24: =INDEX($H$52:$L$56,MATCH(G24,$G$52:$G$56,0),MATCH(H24,$H$51:$L$51,0)) -> Critical | J24: =VLOOKUP(I24, $H$61:$J$64, 3, FALSE) -> 7 | N24: =IF(J24<>"",J24*$M$21,"") -> 1.4 | P24: Focus on service quality differentiation, client satisfaction, and transparent communication to highlight SBS’s professionalism and reliability. Strengthen long-term relationships with clients through regular meetings, trust-based partnerships, and performance reports. | Q24: To maintain client loyalty and competitive advantage by emphasizing service reliability, quality, and compliance — rather than price — ensuring that clients value SBS for long-term trust and performance. | R24: Very Low | S24: Very High | T24: =INDEX($H$52:$L$56,MATCH(R24,$G$52:$G$56,0),MATCH(S24,$H$51:$L$51,0)) -> Severe | U24: =VLOOKUP(T24, $H$61:$J$64, 3, FALSE) -> 5 | Y24: =IF(U24<>"",U24*$X$21,"") -> 1 | Z24: =Y24-N24 -> -0.4 | AA24: {=INDEX($I$84:$I$88,MATCH(1,($Z24>=$G$84:$G$88)*($Z24<=$H$84:$H$88),0))} -> Moderate Improvement
A25: Legal Risks | B25: L1 | C25: Slow Worker Documentation (Contract Non-Compliance) | D25: Delays in completing worker documentation and administrative files (e.g., CNSS registration, ID copies, medical checks) at the start of contracts. Many employees are older and slower to provide required documents, causing minor non-compliance with contract or client requirements. | E25: Administrative non-compliance that may lead to written client observations or temporary delays in payment approval. However, operations continue normally while documents are completed. | F25: HR Manager | G25: High | H25: Low | I25: =INDEX($H$52:$L$56,MATCH(G25,$G$52:$G$56,0),MATCH(H25,$H$51:$L$51,0)) -> Moderate | J25: =VLOOKUP(I25, $H$61:$J$64, 3, FALSE) -> 2 | K25: =AVERAGE(J25:J28) -> 3.25 | L25: {=_xlfn.XLOOKUP(1, (K25>=$G$77:$G$80)*(K25<=$H$77:$H$80), $I$77:$I$80)} -> Moderate | M25: =VLOOKUP($A25, $H$68:$J$72, 3, FALSE) -> 0.2 | N25: =IF(J25<>"",J25*$M$25,"") -> 0.4 | O25: =AVERAGE(N25:N28) -> 0.65 | P25: Simplify and standardize the employee onboarding checklist. Collect and verify all required documents before assigning staff to sites, and assign one HR assistant to follow up on missing paperwork during the first week of each new contract. | Q25: To ensure full legal and administrative compliance from the start of each contract, minimize client observations, and maintain a clean audit trail for CNSS and contractual documentation. | R25: Medium | S25: Low | T25: =INDEX($H$52:$L$56,MATCH(R25,$G$52:$G$56,0),MATCH(S25,$H$51:$L$51,0)) -> Moderate | U25: =VLOOKUP(T25, $H$61:$J$64, 3, FALSE) -> 2 | V25: =AVERAGE(U25:U28) -> 1.75 | W25: {=_xlfn.XLOOKUP(1, (V25>=$G$77:$G$80)*(V25<=$H$77:$H$80), $I$77:$I$80)} -> Sustainable | X25: =VLOOKUP($A25, $H$68:$J$72, 3, FALSE) -> 0.2 | Y25: =IF(U25<>"",U25*$X$25,"") -> 0.4 | Z25: =Y25-N25 -> 0 | AA25: {=INDEX($I$84:$I$88,MATCH(1,($Z25>=$G$84:$G$88)*($Z25<=$H$84:$H$88),0))} -> No Change | AB25: =AVERAGE(Z25:Z28) -> -0.3 | AC25: {=INDEX($I$84:$I$88,MATCH(1,($AB25>=$G$84:$G$88)*($AB25<=$H$84:$H$88),0))} -> Moderate Improvement | AD25: =AVERAGE(Y25:Y28) -> 0.35
B26: L2 | C26: Labor Law Non-Compliance | D26: Potential non-compliance with Tunisian labor law, including excessive overtime, delayed CNSS registration, or employing temporary workers without full documentation. These issues often result from tight deadlines, urgent replacements, or limited HR follow-up. | E26: Exposure to CNSS penalties, labor inspection warnings, or financial sanctions. Repeated violations may damage SBS’s reputation with public clients and delay contract renewals. | F26: HR Manager | G26: Low | H26: Medium | I26: =INDEX($H$52:$L$56,MATCH(G26,$G$52:$G$56,0),MATCH(H26,$H$51:$L$51,0)) -> Moderate | J26: =VLOOKUP(I26, $H$61:$J$64, 3, FALSE) -> 2 | N26: =IF(J26<>"",J26*$M$25,"") -> 0.4 | P26: Strengthen HR monitoring by ensuring timely CNSS registration for all new employees and keeping digital records of declarations. Assign a backup employee to manage administrative compliance and worker replacements during absences or peak periods. | Q26: To ensure full compliance with labor regulations, reduce the risk of fines or client penalties, and maintain SBS’s credibility during audits or inspections. | R26: Very Low | S26: Medium | T26: =INDEX($H$52:$L$56,MATCH(R26,$G$52:$G$56,0),MATCH(S26,$H$51:$L$51,0)) -> Sustainable | U26: =VLOOKUP(T26, $H$61:$J$64, 3, FALSE) -> 0 | Y26: =IF(U26<>"",U26*$X$25,"") -> 0 | Z26: =Y26-N26 -> -0.4 | AA26: {=INDEX($I$84:$I$88,MATCH(1,($Z26>=$G$84:$G$88)*($Z26<=$H$84:$H$88),0))} -> Moderate Improvement
B27: L3 | C27: Late Public Contract Renewals | D27: Uncertainty and delays in the renewal or confirmation of public-sector contracts. SBS often receives final decisions only a few days before contract expiration, leaving limited time to plan staffing, equipment, and logistics for the next period. | E27: Difficulties in workforce allocation and operational planning. The company may temporarily overstaff or understaff sites, causing inefficiencies, idle time, or service gaps. Late notifications can also delay administrative procedures and create financial uncertainty. | F27: General Manager | G27: High | H27: Very High | I27: =INDEX($H$52:$L$56,MATCH(G27,$G$52:$G$56,0),MATCH(H27,$H$51:$L$51,0)) -> Critical | J27: =VLOOKUP(I27, $H$61:$J$64, 3, FALSE) -> 7 | N27: =IF(J27<>"",J27*$M$25,"") -> 1.4 | P27: Maintain regular communication with public procurement offices and contract managers to obtain early visibility on renewal timelines. Prepare staffing and resource scenarios in advance, allowing rapid adjustments once renewal decisions are confirmed. | Q27: To anticipate contract renewals by improving communication with public clients and maintaining flexible operational planning, ensuring uninterrupted service delivery and smoother administrative transitions. | R27: Very Low | S27: Very High | T27: =INDEX($H$52:$L$56,MATCH(R27,$G$52:$G$56,0),MATCH(S27,$H$51:$L$51,0)) -> Severe | U27: =VLOOKUP(T27, $H$61:$J$64, 3, FALSE) -> 5 | Y27: =IF(U27<>"",U27*$X$25,"") -> 1 | Z27: =Y27-N27 -> -0.4 | AA27: {=INDEX($I$84:$I$88,MATCH(1,($Z27>=$G$84:$G$88)*($Z27<=$H$84:$H$88),0))} -> Moderate Improvement
B28: L4 | C28: Work Accident Legal Claims | D28: Potential work-related accidents among cleaning and security staff due to physical tasks, use of chemicals, or lack of safety awareness. These incidents may result in injury claims, CNSS procedures, or legal compensation requests from employees. | E28: Financial exposure through legal compensation or temporary replacement costs. Accidents can also damage SBS’s reputation with clients and lead to increased insurance premiums or inspection frequency. | F28: HR & Safety Officer | G28: Low | H28: Medium | I28: =INDEX($H$52:$L$56,MATCH(G28,$G$52:$G$56,0),MATCH(H28,$H$51:$L$51,0)) -> Moderate | J28: =VLOOKUP(I28, $H$61:$J$64, 3, FALSE) -> 2 | N28: =IF(J28<>"",J28*$M$25,"") -> 0.4 | P28: Conduct regular safety briefings and ensure all employees receive appropriate training on protective equipment and safe working practices. Hire or consult a legal advisor to review accident procedures and ensure compliance with CNSS and labor regulations. | Q28: To minimize the risk of work accidents, strengthen legal compliance, and protect both employees and the company through preventive safety measures and proper incident documentation. | R28: Very Low | S28: Very Low | T28: =INDEX($H$52:$L$56,MATCH(R28,$G$52:$G$56,0),MATCH(S28,$H$51:$L$51,0)) -> Sustainable | U28: =VLOOKUP(T28, $H$61:$J$64, 3, FALSE) -> 0 | Y28: =IF(U28<>"",U28*$X$25,"") -> 0 | Z28: =Y28-N28 -> -0.4 | AA28: {=INDEX($I$84:$I$88,MATCH(1,($Z28>=$G$84:$G$88)*($Z28<=$H$84:$H$88),0))} -> Moderate Improvement
A29: Human Risks | B29: H1 | C29: High Absenteeism (Summer Peaks) | D29: High employee absenteeism, especially during summer months, due to heat, fatigue, or personal commitments. This trend is observed across multiple sites and leads to inconsistent staffing levels and operational disruptions. | E29: Service delays, reduced productivity, and increased workload for available staff, which can cause fatigue, lower morale, and further absenteeism. Prolonged shortages may affect client satisfaction and service continuity. | F29: HR Manager | G29: Medium | H29: High | I29: =INDEX($H$52:$L$56,MATCH(G29,$G$52:$G$56,0),MATCH(H29,$H$51:$L$51,0)) -> Severe | J29: =VLOOKUP(I29, $H$61:$J$64, 3, FALSE) -> 5 | K29: =AVERAGE(J29:J32) -> 4 | L29: {=_xlfn.XLOOKUP(1, (K29>=$G$77:$G$80)*(K29<=$H$77:$H$80), $I$77:$I$80)} -> Moderate | M29: =VLOOKUP($A29, $H$68:$J$72, 3, FALSE) -> 0.2 | N29: =IF(J29<>"",J29*$M$29,"") -> 1 | O29: =AVERAGE(N29:N32) -> 0.8 | P29: Introduce attendance bonuses during summer to motivate presence and punctuality. Implement shift rotation and adjust work schedules to limit exposure to extreme heat and balance workload among teams. | Q29: To reduce absenteeism during high-risk periods by rewarding attendance, improving work conditions, and ensuring operational continuity through better schedule management. | R29: Very Low | S29: High | T29: =INDEX($H$52:$L$56,MATCH(R29,$G$52:$G$56,0),MATCH(S29,$H$51:$L$51,0)) -> Moderate | U29: =VLOOKUP(T29, $H$61:$J$64, 3, FALSE) -> 2 | V29: =AVERAGE(U29:U32) -> 1 | W29: {=_xlfn.XLOOKUP(1, (V29>=$G$77:$G$80)*(V29<=$H$77:$H$80), $I$77:$I$80)} -> Sustainable | X29: =VLOOKUP($A29, $H$68:$J$72, 3, FALSE) -> 0.2 | Y29: =IF(U29<>"",U29*$X$29,"") -> 0.4 | Z29: =Y29-N29 -> -0.6 | AA29: {=INDEX($I$84:$I$88,MATCH(1,($Z29>=$G$84:$G$88)*($Z29<=$H$84:$H$88),0))} -> Strong Improvement | AB29: =AVERAGE(Z29:Z32) -> -0.6 | AC29: {=INDEX($I$84:$I$88,MATCH(1,($AB29>=$G$84:$G$88)*($AB29<=$H$84:$H$88),0))} -> Strong Improvement | AD29: =AVERAGE(Y29:Y32) -> 0.2
B30: H2 | C30: Lack of Training Culture | D30: Absence of a structured training program for employees and supervisors. Most staff learn tasks informally on-site without standardized guidance, which limits skill development, safety awareness, and service quality. | E30: Long-term decline in performance, safety incidents due to lack of awareness, and reduced ability to adapt to new client requirements or technologies. The company becomes dependent on experience rather than skill improvement. | F30: HR Manager | G30: Very High | H30: Low | I30: =INDEX($H$52:$L$56,MATCH(G30,$G$52:$G$56,0),MATCH(H30,$H$51:$L$51,0)) -> Moderate | J30: =VLOOKUP(I30, $H$61:$J$64, 3, FALSE) -> 2 | N30: =IF(J30<>"",J30*$M$29,"") -> 0.4 | P30: Establish an internal peer mentoring and auto-training system where experienced employees train newcomers. Conduct short monthly refreshers on safety, cleaning procedures, and client communication to promote a culture of continuous learning. | Q30: To build internal competencies, enhance safety and service consistency, and reduce external training costs by promoting knowledge sharing and ongoing employee development. | R30: Low | S30: Very Low | T30: =INDEX($H$52:$L$56,MATCH(R30,$G$52:$G$56,0),MATCH(S30,$H$51:$L$51,0)) -> Sustainable | U30: =VLOOKUP(T30, $H$61:$J$64, 3, FALSE) -> 0 | Y30: =IF(U30<>"",U30*$X$29,"") -> 0 | Z30: =Y30-N30 -> -0.4 | AA30: {=INDEX($I$84:$I$88,MATCH(1,($Z30>=$G$84:$G$88)*($Z30<=$H$84:$H$88),0))} -> Moderate Improvement
B31: H3 | C31: Employee Turnover & Shortage | D31: High employee turnover and staff shortages, particularly during summer months when many workers leave for temporary jobs in the tourism sector or abroad. Recruitment delays occur frequently, especially in regional branches where qualified replacements are harder to find. | E31: Service interruptions and reduced performance due to lack of experienced staff. Existing employees face increased workload, lowering morale and further accelerating turnover. | F31: HR Manager | G31: High | H31: High | I31: =INDEX($H$52:$L$56,MATCH(G31,$G$52:$G$56,0),MATCH(H31,$H$51:$L$51,0)) -> Critical | J31: =VLOOKUP(I31, $H$61:$J$64, 3, FALSE) -> 7 | N31: =IF(J31<>"",J31*$M$29,"") -> 1.4 | P31: Introduce a referral bonus of 150 DT for employees who help recruit qualified replacements(Require 2 weeks notice). Maintain a reserve list of part-time or previously trained workers who can be contacted during peak shortages. | Q31: To retain skilled workers and speed up recruitment through internal referrals and proactive workforce planning, ensuring continuity of service even during high-turnover periods. | R31: Medium | S31: Medium | T31: =INDEX($H$52:$L$56,MATCH(R31,$G$52:$G$56,0),MATCH(S31,$H$51:$L$51,0)) -> Moderate | U31: =VLOOKUP(T31, $H$61:$J$64, 3, FALSE) -> 2 | Y31: =IF(U31<>"",U31*$X$29,"") -> 0.4 | Z31: =Y31-N31 -> -1 | AA31: {=INDEX($I$84:$I$88,MATCH(1,($Z31>=$G$84:$G$88)*($Z31<=$H$84:$H$88),0))} -> Strong Improvement
B32: H4 | C32: Workplace Accidents | D32: Possibility of workplace accidents involving cleaning or security staff due to manual handling, use of chemicals, or lack of protective equipment. Some incidents occur because employees underestimate safety risks or skip proper procedures under time pressure. | E32: Medical expenses, CNSS injury claims, and potential loss of working hours. Accidents can also affect team morale and SBS’s credibility with clients if safety incidents occur on their premises. | F32: HR & Safety Officer | G32: Low | H32: Medium | I32: =INDEX($H$52:$L$56,MATCH(G32,$G$52:$G$56,0),MATCH(H32,$H$51:$L$51,0)) -> Moderate | J32: =VLOOKUP(I32, $H$61:$J$64, 3, FALSE) -> 2 | N32: =IF(J32<>"",J32*$M$29,"") -> 0.4 | P32: Conduct monthly safety inspections and provide short first-aid and safety refreshers to all staff. Ensure availability and proper use of personal protective equipment (PPE) at every site. | Q32: To prevent accidents, reduce injury-related costs, and create a safe working environment by promoting continuous awareness of safety practices and ensuring all employees are properly equipped and trained. | R32: Very Low | S32: Medium | T32: =INDEX($H$52:$L$56,MATCH(R32,$G$52:$G$56,0),MATCH(S32,$H$51:$L$51,0)) -> Sustainable | U32: =VLOOKUP(T32, $H$61:$J$64, 3, FALSE) -> 0 | Y32: =IF(U32<>"",U32*$X$29,"") -> 0 | Z32: =Y32-N32 -> -0.4 | AA32: {=INDEX($I$84:$I$88,MATCH(1,($Z32>=$G$84:$G$88)*($Z32<=$H$84:$H$88),0))} -> Moderate Improvement
J33: Total Weightings : | M33: =SUM(M13:M32) -> 1 | O33: =SUM(O13:O32) -> 5.1375 | U33: Total Weightings : | X33: =SUM(X13:X32) -> 1 | AB33: =AVERAGE(Z13:Z32) -> -0.6025 | AD33: =SUM(AD13:AD32) -> 2.125
I36: Rating Before Mitigation | O36: {=_xlfn.XLOOKUP(1, (O33>=$G$77:$G$80)*(O33<=$H$77:$H$80), $I$77:$I$80)} -> Severe | Y36: Mitigation Effect | AB36: {=INDEX($I$84:$I$88,MATCH(1,($AB33>=$G$84:$G$88)*($AB33<=$H$84:$H$88),0))} -> Strong Improvement | AC36: Rating After Mitigation | AD36: {=_xlfn.XLOOKUP(1, (AD33>=$G$77:$G$80)*(AD33<=$H$77:$H$80), $I$77:$I$80)} -> Moderate
F47: Parameters
H51: Very High | I51: High | J51: Medium | K51: Low | L51: Very Low
G52: Very High | H52: Critical | I52: Critical | J52: Severe | K52: Moderate | L52: Moderate
G53: High | H53: Critical | I53: Critical | J53: Severe | K53: Moderate | L53: Sustainable
G54: Medium | H54: Critical | I54: Severe | J54: Moderate | K54: Moderate | L54: Sustainable
G55: Low | H55: Critical | I55: Severe | J55: Moderate | K55: Sustainable | L55: Sustainable
G56: Very Low | H56: Severe | I56: Moderate | J56: Sustainable | K56: Sustainable | L56: Sustainable
H60: Category | I60: Description | J60: Score
H61: Critical | I61: Needs immediate action — unacceptable risk | J61: 7
H62: Severe | I62: High priority — mitigation plan needed | J62: 5
H63: Moderate | I63: Monitor and control | J63: 2
H64: Sustainable | I64: Acceptable or minimal risk | J64: 0
H67: Category | I67: Reasoning | J67: Importance (%)
H68: Operational Risks | I68: SBS success depends on daily cleaning & guarding service quality — operational failure = client loss. | J68: 0.35
H69: Human Risks | I69: Labor-intensive business; service quality fully depends on employees’ reliability and presence. | J69: 0.2
H70: Financial Risks | I70: Cash flow and late client payments strongly affect sustainability. | J70: 0.2
H71: Legal Risks | I71: Compliance with health & safety laws and contracts; essential but manageable. | J71: 0.2
...

Sheet Dashboard 
I2: Dashboard
I6: Category | J6: Pre-Mitigation Risk Level | K6: Mitigation Effect | L6: Post-Mitigation Risk Level
I7: Operational Risks | J7: ='Risk Table'!L13 -> Critical | K7: ='Risk Table'!AC13 -> Strong Improvement | L7: ='Risk Table'!W13 -> Sustainable
I11: Marketing Risks | J11: ='Risk Table'!L17 -> Severe | K11: ='Risk Table'!AC17 -> Slight Improvement | L11: ='Risk Table'!W17 -> Moderate
I15: Financial Risks | J15: ='Risk Table'!L21 -> Severe | K15: ='Risk Table'!AC21 -> Moderate Improvement | L15: ='Risk Table'!W21 -> Moderate
I19: Legal Risks | J19: ='Risk Table'!L25 -> Moderate | K19: ='Risk Table'!AC25 -> Moderate Improvement | L19: ='Risk Table'!W25 -> Sustainable
I23: Human Risks | J23: ='Risk Table'!L29 -> Moderate | K23: ='Risk Table'!AC29 -> Strong Improvement | L23: ='Risk Table'!W29 -> Sustainable
I27: Total Rating | J27: ='Risk Table'!O36 -> Severe | K27: ='Risk Table'!AB36 -> Strong Improvement | L27: ='Risk Table'!AD36 -> Moderate

Sheet CHECKLIST 
D2: CHECKLIST
D5: Status | E5: Item
D6: ✔️​ | E6: Risk Identification
D7: ✔️​ | E7: Risk description
D8: ✔️​ | E8: Risk Category
D9: ✔️​ | E9: Probability (Pre-Mitigation)
D10: ✔️​ | E10: Impact (Pre-Mitigation)
D11: ✔️​ | E11: Risk Score (Pre-Mitigation)
D12: ✔️​ | E12: Rating (Pre-Mitigation)
D13: ✔️​ | E13: Mitigation Measures
D14: ✔️​ | E14: Probability After Mitigation
D15: ✔️​ | E15: Impact After Mitigation
D16: ✔️​ | E16: Residual Risk Score
... D20: ✔️​ | E20: Dashboard Updates Automatically
